<?xml version="1.0"?>
<robot name="RobotArm">

    <material name="blue">
        <color rgba="0 0 1 1"/>
    </material>


<link name="base_link">
        <visual>
            <geometry>
<mesh filename="package://inmoov_description/STL/spalladestra2b.dae" scale="0.009 0.009 0.009" />
            </geometry>
            <origin rpy="4.7 -4.726 -0.03" xyz="-0.1 -1 0.08" />
            <material name="blue"/>
        </visual>
        <collision>
            <geometry>
               <mesh filename="package://inmoov_description/STL/spalladestra2b.dae" scale="0.009 0.009 0.009" />
            </geometry>
          <origin rpy="0 0 0" xyz="0 0 0" />
            <material name="blue"/>
        </collision>
    </link>

    <joint name="joint_spalladx" type="revolute">
        <parent link="base_link"/>
        <child link="spalla2dx_link"/>
      <origin rpy="0 0 -0.02" xyz="0.4 -0.66 -0.41" />
        <axis xyz="1 0 0"/>
        <limit effort="1000" lower="-0.4" upper="0.4" velocity="5"/>
    </joint> 

<link name="spalla2dx_link">
        <visual>
            <geometry>
<mesh filename="package://inmoov_description/STL/spalladestra1a.dae" scale="0.009 0.009 0.009" />
            </geometry>
            <origin rpy="4.7 -4.726 -0.03" xyz="-0.50 -0.39 0.5" />
            <material name="blue"/>
        </visual>
        <collision>
            <geometry>
               <mesh filename="package://inmoov_description/STL/spalladestra1a.dae" scale="0.009 0.009 0.009" />
            </geometry>
          <origin rpy="0 0 0" xyz="0 0 0" />
            <material name="blue"/>
        </collision>
    </link>

    <joint name="joint_bicipitedx" type="revolute">
        <parent link="spalla2dx_link"/>
        <child link="bicipitedx_link"/>
      <origin rpy="0 0 0" xyz="-1.027 0.04 -2.686" />
        <axis xyz="0 0 1"/>
        <limit effort="1000" lower="-0.5" upper="0" velocity="5"/>
    </joint>  


  <link name="bicipitedx_link">
        <visual>
            <geometry>
                 <mesh filename="package://inmoov_description/STL/bicipitedestrotelaio.dae" scale="0.009 0.009 0.009" />
            </geometry>
            <origin rpy="14.13 0 -4.7" xyz="-0.46 -0.43 2.165" />
            <material name="blue"/>
        </visual>
        <collision>
            <geometry>
               <mesh filename="package://inmoov_description/STL/bicipitedestrotelaio.dae" scale="0.009 0.009 0.009" />
            </geometry>
          <origin rpy="0 0 0" xyz="0 0 0" />
            <material name="blue"/>
        </collision>
    </link>

<joint name="joint_servobicipitedx2" type="revolute">
        <parent link="avambracciodx_link"/>
        <child link="servobicipitedx_link"/>
      <origin rpy="0 0 0" xyz="-0.24 -0.15 0.4" />
        <axis xyz="1 0 0"/>
        <limit effort="1000" lower="0.25" upper="0.25" velocity="5"/>
    </joint> 

  <link name="servobicipitedx_link">
        <visual>
            <geometry>
                 <mesh filename="package://inmoov_description/STL/servomotoresinistrobicipite.dae" scale="0.009 0.009 0.009" />
            </geometry>
            <origin rpy="4.7 0 -0.03" xyz="-0.73 -0.44 1.62" />
            <material name="blue"/>
        </visual>
        <collision>
            <geometry>
               <mesh filename="package://inmoov_description/STL/servomotoresinistrobicipite.dae" scale="0.009 0.009 0.009" />
            </geometry>
          <origin rpy="0 0 0" xyz="0 0 0" />
            <material name="blue"/>
        </collision>
    </link>

 <joint name="joint_avambracciodx" type="revolute">
        <parent link="bicipitedx_link"/>
        <child link="avambracciodx_link"/>
     <origin rpy="0 0 0" xyz="-0.04 0.25 0.15" />
        <axis xyz="1 0 0"/>
        <limit effort="1000" lower="-0.4" upper="0" velocity="5"/>
    </joint>  

<link name="avambracciodx_link">
        <visual>
            <geometry>
                 <mesh filename="package://inmoov_description/STL/avambracciodestro.dae" scale="0.009 0.009 0.009" />
            </geometry>
            <origin rpy="0 10.16 0" xyz="1.1 -0.07 -0.74" />
            <material name="blue"/>
        </visual>
        <collision>
            <geometry>
               <mesh filename="package://inmoov_description/STL/avambracciodestro.dae" scale="0.009 0.009 0.009" />
            </geometry>
          <origin rpy="0 0 0" xyz="0 0 0" />
            <material name="blue"/>
        </collision>
    </link>

    <joint name="joint_mano_dx" type="revolute">
        <parent link="avambracciodx_link"/>
        <child link="handdx_link"/>
      <origin rpy="0 3 0" xyz="0.06 -0.11 -0.1" />
        <axis xyz="0 1 0"/>
        <limit effort="1000" lower="0" upper="1.5" velocity="5"/>
    </joint>

<link name="handdx_link">
        <visual>
            <geometry>
                 <mesh filename="package://inmoov_description/STL/manodestra.dae" scale="0.009 0.009 0.009" />
            </geometry>
            <origin rpy="0 1.6 1.55" xyz="0.026 -2.47 0.03" />
            <material name="blue"/>
        </visual>
        <collision>
            <geometry>
               <mesh filename="package://inmoov_description/STL/manodestra.dae" scale="0.009 0.009 0.009" />
            </geometry>
          <origin rpy="7 0 0" xyz="0 -2.4 0" />
            <material name="blue"/>
        </collision>
    </link>

    <joint name="joint_pollicedx1" type="revolute">
        <parent link="handdx_link"/>
        <child link="pollice1dx_link"/>
     <origin rpy="0 0 0" xyz="0.3 -3 0.05" />
        <axis xyz="0 1 0"/>
       <limit effort="1000" lower="0" upper="1.5" velocity="5"/>
    </joint>


    <link name="pollice1dx_link">
        <visual>
            <geometry>
                 <mesh filename="package://inmoov_description/STL/pollice_destro3.dae" scale="0.009 0.009 0.009" />
            </geometry>
            <origin rpy="-0.01 0.25 0.9" xyz="0.53 -0.43 0.3" />
            <material name="blue"/>
        </visual>
        <collision>
            <geometry>
               <mesh filename="package://inmoov_description/STL/pollice_destro3.dae" scale="0.009 0.009 0.009" />
            </geometry>
           <origin rpy="0 0 0" xyz="0 0 0" />
            <material name="blue"/>
        </collision>
    </link>


    <joint name="joint_pollicedx2" type="revolute">
        <parent link="pollice1dx_link"/>
        <child link="pollice2dx_link"/>
        <origin rpy="4.9 5 0.65" xyz="0.25 -0.1 0" />
         <axis xyz="0 1 0"/>
<limit effort="1000" lower="0" upper="1.5" velocity="5"/>
    </joint>


<link name="pollice2dx_link">
        <visual>
            <geometry>
                 <mesh filename="package://inmoov_description/STL/pollice_2.dae" scale="0.009 0.009 0.009" />
            </geometry>
            <origin xyz="0.0 0.0 0.0175"/>
            <material name="blue"/>
        </visual>
        <collision>
            <geometry>
               <mesh filename="package://inmoov_description/STL/pollice_2.dae" scale="0.009 0.009 0.009" />
            </geometry>
             <origin rpy="0 0 0" xyz="0 0 0" />
            <material name="blue"/>
        </collision>
    </link>

    <joint name="joint_pollicedx3" type="revolute">
        <parent link="pollice2dx_link"/>
        <child link="pollice3dx_link"/>
       <origin rpy="0 0 0" xyz="0 0 -0.3" />
        <axis xyz="0 1 0"/>
        <limit effort="1000" lower="0" upper="1.5" velocity="5"/>
    </joint>

<link name="pollice3dx_link">
        <visual>
            <geometry>
                 <mesh filename="package://inmoov_description/STL/pollice_3.dae" scale="0.009 0.009 0.009" />
            </geometry>
            <origin xyz="0 0 0"/>
            <material name="blue"/>
        </visual>
        <collision>
            <geometry>
               <mesh filename="package://inmoov_description/STL/pollice_3.dae" scale="0.009 0.009 0.009" />
            </geometry>
           <origin rpy="9.4 0 0" xyz="0 0 0" />
            <material name="blue"/>
        </collision>
    </link>    

    <joint name="joint_indicedx1" type="revolute">
        <parent link="handdx_link"/>
        <child link="indicedx1_link"/>
      <origin rpy="-3.06 4.7 -1.53" xyz="0.31 -3.553 0.08" />
      <axis xyz="0 1 0"/>
 <limit effort="1000" lower="-1.5" upper="0" velocity="5"/>
    </joint>

   <link name="indicedx1_link">
        <visual>
            <geometry>
                 <mesh filename="package://inmoov_description/STL/indice1.dae" scale="0.009 0.009 0.009" />
            </geometry>
             <origin rpy="0 0 0" xyz="0 0 0.32" />
            <material name="blue"/>
        </visual>
        <collision>
            <geometry>
               <mesh filename="package://inmoov_description/STL/indice1.dae" scale="0.009 0.009 0.009" />
            </geometry>
            <origin rpy="0 0 0" xyz="0 0 0.32" />
            <material name="blue"/>
        </collision>
    </link> 

    <joint name="joint_indicedx2" type="revolute">
        <parent link="indicedx1_link"/>
        <child link="indicedx2_link"/>
        <origin rpy="0 0 0" xyz="0 0 0.35" />
        <axis xyz="0 1 0"/>
        <limit effort="1000" lower="-1.5" upper="0" velocity="5"/>
    </joint>

    <link name="indicedx2_link">
        <visual>
            <geometry>
                 <mesh filename="package://inmoov_description/STL/indice2.dae" scale="0.009 0.009 0.009" />
            </geometry>
            <origin rpy="9.4 0 0" xyz="0 0 -0.025" />
            <material name="blue"/>
        </visual>
        <collision>
            <geometry>
               <mesh filename="package://inmoov_description/STL/indice2.dae" scale="0.009 0.009 0.009" />
            </geometry>
           <origin rpy="9.4 0 0" xyz="0 0 -0.025" />
            <material name="blue"/>
        </collision>
    </link> 

    <joint name="joint_indicedx3" type="revolute">
        <parent link="indicedx2_link"/>
        <child link="indicedx3_link"/>
      <origin rpy="0 0 0" xyz="0 0.005 0.2" />
      <axis xyz="0 1 0"/>
 <limit effort="1000" lower="-1.5" upper="0" velocity="5"/>
    </joint>

    <link name="indicedx3_link">
        <visual>
            <geometry>
                 <mesh filename="package://inmoov_description/STL/indice3.dae" scale="0.009 0.009 0.009" />
            </geometry>
            <origin rpy="9.4 0 0" xyz="0 0 -0.01" />
            <material name="blue"/>
        </visual>
        <collision>
            <geometry>
               <mesh filename="package://inmoov_description/STL/indice3.dae" scale="0.009 0.009 0.009" />
            </geometry>
             <origin rpy="9.4 0 0" xyz="0 0 -0.01" />
            <material name="blue"/>
        </collision>
    </link> 

    <joint name="joint_mediodx1" type="revolute">
        <parent link="handdx_link"/>
        <child link="mediodx1_link"/>
       <origin rpy="-3.14 4.7 -1.565" xyz="0.065 -3.58 0.08" />
        <axis xyz="0 1 0"/>
       <limit effort="1000" lower="-1.5" upper="0" velocity="5"/>
    </joint>

    <link name="mediodx1_link">
        <visual>
            <geometry>
                 <mesh filename="package://inmoov_description/STL/medio_1.dae" scale="0.009 0.009 0.009" />
            </geometry>
           <origin rpy="0 0 0" xyz="0 0 0.35" />
            <material name="blue"/>
        </visual>
        <collision>
            <geometry>
               <mesh filename="package://inmoov_description/STL/medio_1.dae" scale="0.009 0.009 0.009" />
            </geometry>
             <origin rpy="0 0 0" xyz="0 0 0.35" />
            <material name="blue"/>
        </collision>
    </link> 

    <joint name="joint_mediodx2" type="revolute">
        <parent link="mediodx1_link"/>
        <child link="mediodx2_link"/>
          <origin rpy="0 0 0" xyz="0 0 0.35" />
        <axis xyz="0 1 0"/>
        <limit effort="1000" lower="-1.5" upper="0" velocity="5"/>
    </joint>

    <link name="mediodx2_link">
        <visual>
            <geometry>
                 <mesh filename="package://inmoov_description/STL/medio_2.dae" scale="0.009 0.009 0.009" />
            </geometry>
              <origin rpy="9.4 0 0" xyz="0 0 0.015" />
            <material name="blue"/>
        </visual>
        <collision>
            <geometry>
               <mesh filename="package://inmoov_description/STL/medio_2.dae" scale="0.009 0.009 0.009" />
            </geometry>
             <origin rpy="9.4 0 0" xyz="0 0 0.015" />
            <material name="blue"/>
        </collision>
    </link> 

    <joint name="joint_mediodx3" type="revolute">
        <parent link="mediodx2_link"/>
        <child link="mediodx3_link"/>
         <origin rpy="0 0 0" xyz="0 0 0.22" />
      <axis xyz="0 1 0"/>
 <limit effort="1000" lower="-1.5" upper="0" velocity="5"/>    
   </joint>

    <link name="mediodx3_link">
        <visual>
            <geometry>
                 <mesh filename="package://inmoov_description/STL/medio_3.dae" scale="0.009 0.009 0.009" />
            </geometry>
             <origin rpy="9.4 0 0" xyz="0 0 0.02" />
            <material name="blue"/>
        </visual>
        <collision>
            <geometry>
               <mesh filename="package://inmoov_description/STL/medio_3.dae" scale="0.009 0.009 0.009" />
            </geometry>
             <origin rpy="9.4 0 0" xyz="0 0 0.02" />
            <material name="blue"/>
        </collision>
    </link> 


     <joint name="joint_anularedx1" type="revolute">
        <parent link="handdx_link"/>
        <child link="anulare1dx_link"/>
       <origin rpy="-3.22 4.7 -1.565" xyz="-0.22 -3.495 0.08" />
        <axis xyz="0 1 0"/>
        <limit effort="1000" lower="-1.5" upper="0" velocity="5"/>
    </joint>

    <link name="anulare1dx_link">
        <visual>
            <geometry>
                 <mesh filename="package://inmoov_description/STL/anulare_2.dae" scale="0.009 0.009 0.009" />
            </geometry>
              <origin rpy="9.4 0 0" xyz="0 0 0" />
            <material name="blue"/>
        </visual>
        <collision>
            <geometry>
               <mesh filename="package://inmoov_description/STL/anulare_2.dae" scale="0.009 0.009 0.009" />
            </geometry>
             <origin rpy="9.4 0 0" xyz="0 0 0" />
            <material name="blue"/>
        </collision>
    </link> 

    <joint name="joint_anularedx2" type="revolute">
        <parent link="anulare1dx_link"/>
        <child link="anulare2dx_link"/>
         <origin rpy="0 0 0" xyz="0 0 0.32" />
      <axis xyz="0 1 0"/>
 <limit effort="1000" lower="-1.5" upper="0" velocity="5"/>
    </joint>

    <link name="anulare2dx_link">
        <visual>
            <geometry>
                 <mesh filename="package://inmoov_description/STL/anulare_3.dae" scale="0.009 0.009 0.009" />
            </geometry>
             <origin rpy="9.4 0 0" xyz="0 0 0" />
            <material name="blue"/>
        </visual>
        <collision>
            <geometry>
               <mesh filename="package://inmoov_description/STL/anulare_3.dae" scale="0.009 0.009 0.009" />
            </geometry>
             <origin rpy="9.4 0 0" xyz="0 0 0.02" />
            <material name="blue"/>
        </collision>
    </link> 

 <joint name="joint_anularedx3" type="revolute">
        <parent link="anulare2dx_link"/>
        <child link="anulare3dx_link"/>
         <origin rpy="0 0 0" xyz="0 0 0.2" />
      <axis xyz="0 1 0"/>
<limit effort="1000" lower="-1.5" upper="0" velocity="5"/>
    </joint>

    <link name="anulare3dx_link">
        <visual>
            <geometry>
                 <mesh filename="package://inmoov_description/STL/anulare_4.dae" scale="0.009 0.009 0.009" />
            </geometry>
             <origin rpy="9.4 0 0" xyz="0 0 0" />
            <material name="blue"/>
        </visual>
        <collision>
            <geometry>
               <mesh filename="package://inmoov_description/STL/anulare_4.dae" scale="0.009 0.009 0.009" />
            </geometry>
             <origin rpy="9.4 0 0" xyz="0 0 0" />
            <material name="blue"/>
        </collision>
    </link> 


 <joint name="joint_mignolodx1" type="revolute">
        <parent link="handdx_link"/>
        <child link="linkdx_mignoloprimo"/>
       <origin rpy="-0.225 4.7 -1.565" xyz="-0.437 -3.38 0.08" />
        <axis xyz="0 1 0"/>
       <limit effort="1000" lower="0" upper="1.5" velocity="5"/>
    </joint>

    <link name="linkdx_mignoloprimo">
        <visual>
            <geometry>
                 <mesh filename="package://inmoov_description/STL/mignolo_2.dae" scale="0.009 0.009 0.009" />
            </geometry>
           <origin rpy="0 0 0" xyz="0 0 0" />
            <material name="blue"/>
        </visual>
        <collision>
            <geometry>
               <mesh filename="package://inmoov_description/STL/mignolo_2.dae" scale="0.009 0.009 0.009" />
            </geometry>
             <origin rpy="0 0 0" xyz="0 0 0" />
            <material name="blue"/>
        </collision>
    </link> 

<joint name="joint_mignolodx2" type="revolute">
        <parent link="linkdx_mignoloprimo"/>
        <child link="linkdx_mignolosecondo"/>
       <origin rpy="0 0 0" xyz="0 0 -0.3" />
        <axis xyz="0 1 0"/>
       <limit effort="1000" lower="0" upper="1.5" velocity="5"/>
    </joint>

    <link name="linkdx_mignolosecondo">
        <visual>
            <geometry>
                 <mesh filename="package://inmoov_description/STL/mignolo_3.dae" scale="0.009 0.009 0.009" />
            </geometry>
           <origin rpy="0 0 0" xyz="0 0 0" />
            <material name="blue"/>
        </visual>
        <collision>
            <geometry>
               <mesh filename="package://inmoov_description/STL/mignolo_3.dae" scale="0.009 0.009 0.009" />
            </geometry>
             <origin rpy="0 0 0" xyz="0 0 0" />
            <material name="blue"/>
        </collision>
    </link> 

<joint name="joint_mignolodx3" type="revolute">
        <parent link="linkdx_mignolosecondo"/>
        <child link="linkdx_mignoloterzo"/>
       <origin rpy="0 0 0" xyz="0 0 -0.2" />
        <axis xyz="0 1 0"/>
        <limit effort="1000" lower="0" upper="1.5" velocity="5"/>
    </joint>

    <link name="linkdx_mignoloterzo">
        <visual>
            <geometry>
                 <mesh filename="package://inmoov_description/STL/mignolo_4.dae" scale="0.009 0.009 0.009" />
            </geometry>
           <origin rpy="0 0 0" xyz="0 0 0" />
            <material name="blue"/>
        </visual>
        <collision>
            <geometry>
               <mesh filename="package://inmoov_description/STL/mignolo_4.dae" scale="0.009 0.009 0.009" />
            </geometry>
             <origin rpy="0 0 0" xyz="0 0 0" />
            <material name="blue"/>
        </collision>
    </link> 


     

</robot>
