<?xml version="1.0"?>
<robot name="RobotArm">

    <material name="blue">                     
        <color rgba="0 0 1 1"/>
    </material>


    <link name="base_link">
        <visual>
            <geometry>
                 <mesh filename="package://inmoov_description/STL/stomaco_medio.dae" scale="0.009 0.009 0.009" />
            </geometry>
            <origin rpy="-1.56 3.12 3.13" xyz="1.86 0.02 1.94" />
            <material name="blue"/>
        </visual>
        <collision>
            <geometry>
               <mesh filename="package://inmoov_description/STL/stomaco_medio.dae" scale="0.009 0.009 0.009" />
            </geometry>
          <origin rpy="0 0 0" xyz="0 0 0" />
            <material name="blue"/>
        </collision>
    </link>

    <joint name="joint_stomaco" type="revolute">
        <parent link="base_link"/>
        <child link="stomaco_link"/>
      <origin rpy="-1.56 0.02 0" xyz="1.35 -0.37 2.05" />
        <axis xyz="0 1 0"/>
        <limit effort="1000" lower="-0.5" upper="0.5" velocity="5"/>
    </joint>

<link name="stomaco_link">
        <visual>
            <geometry>
                 <mesh filename="package://inmoov_description/STL/stomaco_alto.dae" scale="0.009 0.009 0.009" />
            </geometry>
            <origin rpy="0.05 0 0" xyz="-0.54 0.1 -0.35" />
            <material name="blue"/>
        </visual>
        <collision>
            <geometry>
               <mesh filename="package://inmoov_description/STL/stomaco_alto.dae" scale="0.009 0.009 0.009" />
            </geometry>
          <origin rpy="0 0 0" xyz="0 0 0" />
            <material name="blue"/>
        </collision>
    </link>

 <joint name="joint_torso" type="revolute">
        <parent link="stomaco_link"/>
        <child link="torso_link"/>
      <origin rpy="1.56 0.02 0" xyz="-0.05 -1 0" />
        <axis xyz="0 1 0"/>
        <limit effort="1000" lower="-0.15" upper="0.15" velocity="5"/>
    </joint>

<link name="torso_link">
        <visual>
            <geometry>
                 <mesh filename="package://inmoov_description/STL/busto.dae" scale="0.009 0.009 0.009" />
            </geometry>
            <origin rpy="0 0 0" xyz="0 -0.32 2.5" />
            <material name="blue"/>
        </visual>
        <collision>
            <geometry>
               <mesh filename="package://inmoov_description/STL/busto.dae" scale="0.009 0.009 0.009" />
            </geometry>
          <origin rpy="0 0 0" xyz="0 0 0" />
            <material name="blue"/>
        </collision>
    </link>

<joint name="joint_collo" type="fixed">
        <parent link="torso_link"/>
        <child link="collo_link"/>
      <origin rpy="1.56 0.02 0" xyz="0 0 0" />
        <axis xyz="0 1 0"/>
        <limit effort="1000" lower="-0.12" upper="0.12" velocity="5"/>
    </joint>

<link name="collo_link">
        <visual>
            <geometry>
                 <mesh filename="package://inmoov_description/STL/collo.dae" scale="0.009 0.009 0.009" />
            </geometry>
            <origin rpy="0 0 0" xyz="-0.069 4.055 -0.255" />
            <material name="blue"/>
        </visual>
        <collision>
            <geometry>
               <mesh filename="package://inmoov_description/STL/collo.dae" scale="0.009 0.009 0.009" />
            </geometry>
          <origin rpy="0 0 0" xyz="0 0 0" />
            <material name="blue"/>
        </collision>
    </link>

<joint name="joint_testa" type="revolute">
        <parent link="collo_link"/>
        <child link="testa_link"/>
      <origin rpy="0 0 0" xyz="-0.07 4.05 -0.21" />
        <axis xyz="1 0 0"/>
        <limit effort="1000" lower="-0.2" upper="0.2" velocity="5"/>
    </joint>

<link name="testa_link">
        <visual>
            <geometry>
                 <mesh filename="package://inmoov_description/STL/testa.dae" scale="0.009 0.009 0.009" />
            </geometry>
            <origin rpy="0 0 0" xyz="0 0 0" />
            <material name="blue"/>
        </visual>
        <collision>
            <geometry>
               <mesh filename="package://inmoov_description/STL/testa.dae" scale="0.009 0.009 0.009" />
            </geometry>
          <origin rpy="0 0 0" xyz="0 0 0" />
            <material name="blue"/>
        </collision>
    </link>


 
 <joint name="spallatorsosx2_joint" type="revolute">
        <parent link="torso_link"/>
        <child link="spallasx1_link"/>
      <origin rpy="0 0 0" xyz="1.25 0.535 2.6" />
        <axis xyz="0 1 0"/>
        <limit effort="1000" lower="-0.5" upper="0" velocity="5"/>
    </joint>

<link name="spallasx1_link">
        <visual>
            <geometry>
<mesh filename="package://inmoov_description/STL/spallasinistraparte2a.dae" scale="0.009 0.009 0.009" />
            </geometry>
            <origin rpy="4.7 4.747 -0.03" xyz="0.11 -1 -0.91" />
            <material name="blue"/>
        </visual>
        <collision>
            <geometry>
               <mesh filename="package://inmoov_description/STL/spallasinistraparte2a.dae" scale="0.009 0.009 0.009" />
            </geometry>
          <origin rpy="0 0 0" xyz="0 0 0" />
            <material name="blue"/>
        </collision>
    </link>

    <joint name="joint_spallasx" type="revolute">
        <parent link="spallasx1_link"/>
        <child link="spallasx2_link"/>
      <origin rpy="0 0 -0.02" xyz="0.61 -0.66 -0.31" />
        <axis xyz="1 0 0"/>
        <limit effort="1000" lower="-0.4" upper="0.4" velocity="5"/>
    </joint> 

<link name="spallasx2_link">
        <visual>
            <geometry>
<mesh filename="package://inmoov_description/STL/spallasxparte1b.dae" scale="0.009 0.009 0.009" />
            </geometry>
            <origin rpy="4.7 4.747 -0.03" xyz="-0.50 -0.34 -0.6" />
            <material name="blue"/>
        </visual>
        <collision>
            <geometry>
               <mesh filename="package://inmoov_description/STL/spallasxparte1b.dae" scale="0.009 0.009 0.009" />
            </geometry>
          <origin rpy="0 0 0" xyz="0 0 0" />
            <material name="blue"/>
        </collision>
    </link>

    <joint name="joint_bicipitesx" type="revolute">
        <parent link="spallasx2_link"/>
        <child link="bicipitesx_link"/>
      <origin rpy="0 0 0" xyz="0.165 0.06 -2.595" />
        <axis xyz="0 0 1"/>
        <limit effort="1000" lower="0" upper="0.5" velocity="5"/>
    </joint>  

  <link name="bicipitesx_link">
        <visual>
            <geometry>
                 <mesh filename="package://inmoov_description/STL/bicipitesxtelaio.dae" scale="0.009 0.009 0.009" />
            </geometry>
            <origin rpy="4.7 0 -0.03" xyz="-1.028 -0.36 2.01" />
            <material name="blue"/>
        </visual>
        <collision>
            <geometry>
               <mesh filename="package://inmoov_description/STL/bicipitesxtelaio.dae" scale="0.009 0.009 0.009" />
            </geometry>
          <origin rpy="0 0 0" xyz="0 0 0" />
            <material name="blue"/>
        </collision>
    </link>

<joint name="joint_servobicipitesx2" type="revolute">
        <parent link="avambracciosx_link"/>
        <child link="servobicipitesx_link"/>
      <origin rpy="0 0 0" xyz="-0.14 -0.15 0.4" />
        <axis xyz="1 0 0"/>
        <limit effort="1000" lower="0.15" upper="0.15" velocity="5"/>
    </joint> 

  <link name="servobicipitesx_link">
        <visual>
            <geometry>
                 <mesh filename="package://inmoov_description/STL/servomotoresinistrobicipite.dae" scale="0.009 0.009 0.009" />
            </geometry>
            <origin rpy="4.7 0 -0.03" xyz="-1.02 -0.455 1.64" />
            <material name="blue"/>
        </visual>
        <collision>
            <geometry>
               <mesh filename="package://inmoov_description/STL/servomotoresinistrobicipite.dae" scale="0.009 0.009 0.009" />
            </geometry>
          <origin rpy="0 0 0" xyz="0 0 0" />
            <material name="blue"/>
        </collision>
    </link>


    <joint name="joint_avambracciosx" type="revolute">
        <parent link="bicipitesx_link"/>
        <child link="avambracciosx_link"/>
      <origin rpy="0 0 0" xyz="0.16 0.23 -0.04" />
        <axis xyz="1 0 0"/>
        <limit effort="1000" lower="-0.3" upper="0" velocity="5"/>
    </joint>  

  <link name="avambracciosx_link">
        <visual>
            <geometry>
                 <mesh filename="package://inmoov_description/STL/avambraccio_sx.dae" scale="0.009 0.009 0.009" />
            </geometry>
            <origin rpy="0 8.75 0" xyz="-0.14 -0.11 -0.13" />
            <material name="blue"/>
        </visual>
        <collision>
            <geometry>
               <mesh filename="package://inmoov_description/STL/avambraccio_sx.dae" scale="0.009 0.009 0.009" />
            </geometry>
          <origin rpy="0 0 0" xyz="0 0 0" />
            <material name="blue"/>
        </collision>
    </link>

    <joint name="joint_mano_sx" type="revolute">
        <parent link="avambracciosx_link"/>
        <child link="handsx_link"/>
      <origin rpy="0 0 0" xyz="-0.34 -0.12 -0.13" />
        <axis xyz="0 1 0"/>
        <limit effort="1000" lower="-1.5" upper="0" velocity="5"/>
    </joint>

<link name="handsx_link">
        <visual>
            <geometry>
                 <mesh filename="package://inmoov_description/STL/mano_sinistra.dae" scale="0.009 0.009 0.009" />
            </geometry>
            <origin rpy="0 1.6 1.55" xyz="0.026 -2.47 0.03" />
            <material name="blue"/>
        </visual>
        <collision>
            <geometry>
               <mesh filename="package://inmoov_description/STL/mano_sinistra.dae" scale="0.009 0.009 0.009" />
            </geometry>
          <origin rpy="7 0 0" xyz="0 -2.4 0" />
            <material name="blue"/>
        </collision>
    </link>

    <joint name="joint_pollice1sx" type="revolute">
        <parent link="handsx_link"/>
        <child link="pollice1sx_link"/>
     <origin rpy="0 0 0" xyz="0.3 -3 0.05" />
        <axis xyz="0 1 0"/>
        <limit effort="1000" lower="-0.5" upper="0" velocity="5"/>
    </joint>


    <link name="pollice1sx_link">
        <visual>
            <geometry>
                 <mesh filename="package://inmoov_description/STL/pollice_sx_1.dae" scale="0.009 0.009 0.009" />
            </geometry>
            <origin rpy="0.25 1.5 1.7" xyz="0 0 0" />
            <material name="blue"/>
        </visual>
        <collision>
            <geometry>
               <mesh filename="package://inmoov_description/STL/pollice_sx_1.dae" scale="0.009 0.009 0.009" />
            </geometry>
           <origin rpy="-3.25 -12.5 3.2" xyz="0.2 -3 -0.2" />
            <material name="blue"/>
        </collision>
    </link>


    <joint name="joint_pollice2sx" type="revolute">
        <parent link="pollice1sx_link"/>
        <child link="pollice2sx_link"/>
        <origin rpy="4.9 1.3 1" xyz="0.2 -0.1 0" />
         <axis xyz="0 1 0"/>
 <limit effort="1000" lower="0" upper="1.5" velocity="5"/>
    </joint>


<link name="pollice2sx_link">
        <visual>
            <geometry>
                 <mesh filename="package://inmoov_description/STL/pollice_2.dae" scale="0.009 0.009 0.009" />
            </geometry>
            <origin xyz="0.0 0.0 0.0175"/>
            <material name="blue"/>
        </visual>
        <collision>
            <geometry>
               <mesh filename="package://inmoov_description/STL/pollice_2.dae" scale="0.009 0.009 0.009" />
            </geometry>
             <origin rpy="0 0 0" xyz="0 0 0" />
            <material name="blue"/>
        </collision>
    </link>

    <joint name="joint_pollice3sx" type="revolute">
        <parent link="pollice2sx_link"/>
        <child link="pollice3sx_link"/>
       <origin rpy="0 0 0" xyz="0 0 -0.3" />
        <axis xyz="0 1 0"/>
        <limit effort="1000" lower="0" upper="1.5" velocity="5"/>
    </joint>

<link name="pollice3sx_link">
        <visual>
            <geometry>
                 <mesh filename="package://inmoov_description/STL/pollice_3.dae" scale="0.009 0.009 0.009" />
            </geometry>
            <origin xyz="0 0 0"/>
            <material name="blue"/>
        </visual>
        <collision>
            <geometry>
               <mesh filename="package://inmoov_description/STL/pollice_3.dae" scale="0.009 0.009 0.009" />
            </geometry>
           <origin rpy="9.4 0 0" xyz="0 0 0" />
            <material name="blue"/>
        </collision>
    </link>    

    <joint name="joint_indice1sx" type="revolute">
        <parent link="handsx_link"/>
        <child link="indice1sx_link"/>
      <origin rpy="0 -4.7 -1.53" xyz="0.31 -3.553 0.08" />
      <axis xyz="0 1 0"/>
 <limit effort="1000" lower="-1" upper="0" velocity="5"/>
    </joint>

   <link name="indice1sx_link">
        <visual>
            <geometry>
                 <mesh filename="package://inmoov_description/STL/indice1.dae" scale="0.009 0.009 0.009" />
            </geometry>
             <origin rpy="0 0 0" xyz="0 0 0.32" />
            <material name="blue"/>
        </visual>
        <collision>
            <geometry>
               <mesh filename="package://inmoov_description/STL/indice1.dae" scale="0.009 0.009 0.009" />
            </geometry>
            <origin rpy="0 0 0" xyz="0 0 0.32" />
            <material name="blue"/>
        </collision>
    </link> 

    <joint name="joint_indice2sx" type="revolute">
        <parent link="indice1sx_link"/>
        <child link="indice2sx_link"/>
        <origin rpy="0 0 0" xyz="0 0 0.35" />
        <axis xyz="0 1 0"/>
         <limit effort="1000" lower="-1.5" upper="0" velocity="5"/>
    </joint>

    <link name="indice2sx_link">
        <visual>
            <geometry>
                 <mesh filename="package://inmoov_description/STL/indice2.dae" scale="0.009 0.009 0.009" />
            </geometry>
            <origin rpy="9.4 0 0" xyz="0 0 -0.025" />
            <material name="blue"/>
        </visual>
        <collision>
            <geometry>
               <mesh filename="package://inmoov_description/STL/indice2.dae" scale="0.009 0.009 0.009" />
            </geometry>
           <origin rpy="9.4 0 0" xyz="0 0 -0.025" />
            <material name="blue"/>
        </collision>
    </link> 

    <joint name="joint_indice3sx" type="revolute">
        <parent link="indice2sx_link"/>
        <child link="indice3sx_link"/>
      <origin rpy="0 0 0" xyz="0 0.005 0.2" />
      <axis xyz="0 1 0"/>
  <limit effort="1000" lower="-1.5" upper="0" velocity="5"/>
    </joint>

    <link name="indice3sx_link">
        <visual>
            <geometry>
                 <mesh filename="package://inmoov_description/STL/indice3.dae" scale="0.009 0.009 0.009" />
            </geometry>
            <origin rpy="9.4 0 0" xyz="0 0 -0.01" />
            <material name="blue"/>
        </visual>
        <collision>
            <geometry>
               <mesh filename="package://inmoov_description/STL/indice3.dae" scale="0.009 0.009 0.009" />
            </geometry>
             <origin rpy="9.4 0 0" xyz="0 0 -0.01" />
            <material name="blue"/>
        </collision>
    </link> 

    <joint name="joint_medio1sx" type="revolute">
        <parent link="handsx_link"/>
        <child link="medio1sx_link"/>
       <origin rpy="0 -4.7 -1.565" xyz="0.065 -3.58 0.08" />
        <axis xyz="0 1 0"/>
       <limit effort="1000" lower="-1.5" upper="0" velocity="5"/>
    </joint>

    <link name="medio1sx_link">
        <visual>
            <geometry>
                 <mesh filename="package://inmoov_description/STL/medio_1.dae" scale="0.009 0.009 0.009" />
            </geometry>
           <origin rpy="0 0 0" xyz="0 0 0.35" />
            <material name="blue"/>
        </visual>
        <collision>
            <geometry>
               <mesh filename="package://inmoov_description/STL/medio_1.dae" scale="0.009 0.009 0.009" />
            </geometry>
             <origin rpy="0 0 0" xyz="0 0 0.35" />
            <material name="blue"/>
        </collision>
    </link> 

    <joint name="joint_medio2sx" type="revolute">
        <parent link="medio1sx_link"/>
        <child link="medio2sx_link"/>
          <origin rpy="0 0 0" xyz="0 0 0.35" />
        <axis xyz="0 1 0"/>
         <limit effort="1000" lower="-1.5" upper="0" velocity="5"/>
    </joint>

    <link name="medio2sx_link">
        <visual>
            <geometry>
                 <mesh filename="package://inmoov_description/STL/medio_2.dae" scale="0.009 0.009 0.009" />
            </geometry>
              <origin rpy="9.4 0 0" xyz="0 0 0.015" />
            <material name="blue"/>
        </visual>
        <collision>
            <geometry>
               <mesh filename="package://inmoov_description/STL/medio_2.dae" scale="0.009 0.009 0.009" />
            </geometry>
             <origin rpy="9.4 0 0" xyz="0 0 0.015" />
            <material name="blue"/>
        </collision>
    </link> 

    <joint name="joint_medio3sx" type="revolute">
        <parent link="medio2sx_link"/>
        <child link="medio3sx_link"/>
         <origin rpy="0 0 0" xyz="0 0 0.22" />
      <axis xyz="0 1 0"/>
  <limit effort="1000" lower="-1.5" upper="0" velocity="5"/>
    </joint>

    <link name="medio3sx_link">
        <visual>
            <geometry>
                 <mesh filename="package://inmoov_description/STL/medio_3.dae" scale="0.009 0.009 0.009" />
            </geometry>
             <origin rpy="9.4 0 0" xyz="0 0 0.02" />
            <material name="blue"/>
        </visual>
        <collision>
            <geometry>
               <mesh filename="package://inmoov_description/STL/medio_3.dae" scale="0.009 0.009 0.009" />
            </geometry>
             <origin rpy="9.4 0 0" xyz="0 0 0.02" />
            <material name="blue"/>
        </collision>
    </link> 

   <joint name="joint_anularesx1" type="revolute">
        <parent link="handsx_link"/>
        <child link="anulare1sx_link"/>
       <origin rpy="-0.7 1.5 1.5" xyz="0 -3.2 0.05" />
        <axis xyz="0 0 1"/>
           <limit effort="1000" lower="0" upper="0.5" velocity="5"/>
    </joint>

    <link name="anulare1sx_link">
        <visual>
            <geometry>
                 <mesh filename="package://inmoov_description/STL/anulare_sx_1.dae" scale="0.009 0.009 0.009" />
            </geometry>
           <origin rpy="0 0 0" xyz="0 0 0.05" />
            <material name="blue"/>
        </visual>
        <collision>
            <geometry>
               <mesh filename="package://inmoov_description/STL/anulare_sx_1.dae" scale="0.009 0.009 0.009" />
            </geometry>
             <origin rpy="0 0 0" xyz="0 0 0.35" />
            <material name="blue"/>
        </collision>
    </link> 

    <joint name="joint_anulare2sx" type="revolute">
        <parent link="anulare1sx_link"/>
        <child link="anulare2sx_link"/>
          <origin rpy="-2.5 0 0" xyz="0 0.3 -0.08" />
        <axis xyz="0 1 0"/>
         <limit effort="1000" lower="-1.5" upper="0" velocity="5"/>
    </joint>

    <link name="anulare2sx_link">
        <visual>
            <geometry>
                 <mesh filename="package://inmoov_description/STL/anulare_2.dae" scale="0.009 0.009 0.009" />
            </geometry>
              <origin rpy="9.4 0 0" xyz="0 0 0" />
            <material name="blue"/>
        </visual>
        <collision>
            <geometry>
               <mesh filename="package://inmoov_description/STL/anulare_2.dae" scale="0.009 0.009 0.009" />
            </geometry>
             <origin rpy="9.4 0 0" xyz="0 0 0" />
            <material name="blue"/>
        </collision>
    </link> 

    <joint name="joint_anulare3sx" type="revolute">
        <parent link="anulare2sx_link"/>
        <child link="anulare3sx_link"/>
         <origin rpy="0 0 0" xyz="0 0 0.32" />
      <axis xyz="0 1 0"/>
  <limit effort="1000" lower="-1.5" upper="0" velocity="5"/>
    </joint>

    <link name="anulare3sx_link">
        <visual>
            <geometry>
                 <mesh filename="package://inmoov_description/STL/anulare_3.dae" scale="0.009 0.009 0.009" />
            </geometry>
             <origin rpy="9.4 0 0" xyz="0 0 0" />
            <material name="blue"/>
        </visual>
        <collision>
            <geometry>
               <mesh filename="package://inmoov_description/STL/anulare_3.dae" scale="0.009 0.009 0.009" />
            </geometry>
             <origin rpy="9.4 0 0" xyz="0 0 0.02" />
            <material name="blue"/>
        </collision>
    </link> 

 <joint name="joint_anulare4sx" type="revolute">
        <parent link="anulare3sx_link"/>
        <child link="anulare4sx_link"/>
         <origin rpy="0 0 0" xyz="0 0 0.22" />
      <axis xyz="0 1 0"/>
  <limit effort="1000" lower="-1.5" upper="0" velocity="5"/>
    </joint>

    <link name="anulare4sx_link">
        <visual>
            <geometry>
                 <mesh filename="package://inmoov_description/STL/anulare_4.dae" scale="0.009 0.009 0.009" />
            </geometry>
             <origin rpy="9.4 0 0" xyz="0 0 0" />
            <material name="blue"/>
        </visual>
        <collision>
            <geometry>
               <mesh filename="package://inmoov_description/STL/anulare_4.dae" scale="0.009 0.009 0.009" />
            </geometry>
             <origin rpy="9.4 0 0" xyz="0 0 0" />
            <material name="blue"/>
        </collision>
    </link> 

 <joint name="joint_mignolosx" type="revolute">
        <parent link="handsx_link"/>
        <child link="link_mignoloprimosx"/>
       <origin rpy="-0.7 1.48 1.5" xyz="-0.2 -2.9 0.05" />
        <axis xyz="0 0 1"/>
        <limit effort="1000" lower="0" upper="0.5" velocity="5"/>
    </joint>

    <link name="link_mignoloprimosx">
        <visual>
            <geometry>
                 <mesh filename="package://inmoov_description/STL/mignolo_sx_1.dae" scale="0.009 0.009 0.009" />
            </geometry>
           <origin rpy="0 0 0" xyz="0 0 0" />
            <material name="blue"/>
        </visual>
        <collision>
            <geometry>
               <mesh filename="package://inmoov_description/STL/mignolo_sx_1.dae" scale="0.009 0.009 0.009" />
            </geometry>
             <origin rpy="0 0 0" xyz="0 0 0" />
            <material name="blue"/>
        </collision>
    </link> 

<joint name="joint_mignolo2sx" type="revolute">
        <parent link="link_mignoloprimosx"/>
        <child link="link_mignolosecondosx"/>
       <origin rpy="0.9 0 0" xyz="0 0.45 -0.23" />
        <axis xyz="0 1 0"/>
         <limit effort="1000" lower="0" upper="1.5" velocity="5"/>
    </joint>

    <link name="link_mignolosecondosx">
        <visual>
            <geometry>
                 <mesh filename="package://inmoov_description/STL/mignolo_2.dae" scale="0.009 0.009 0.009" />
            </geometry>
           <origin rpy="0 0 0" xyz="0 0 0" />
            <material name="blue"/>
        </visual>
        <collision>
            <geometry>
               <mesh filename="package://inmoov_description/STL/mignolo_2.dae" scale="0.009 0.009 0.009" />
            </geometry>
             <origin rpy="0 0 0" xyz="0 0 0" />
            <material name="blue"/>
        </collision>
    </link> 

<joint name="joint_mignolo3sx" type="revolute">
        <parent link="link_mignolosecondosx"/>
        <child link="link_mignoloterzosx"/>
       <origin rpy="0 0 0" xyz="0 0 -0.3" />
        <axis xyz="0 1 0"/>
          <limit effort="1000" lower="0" upper="1.5" velocity="5"/>
    </joint>

    <link name="link_mignoloterzosx">
        <visual>
            <geometry>
                 <mesh filename="package://inmoov_description/STL/mignolo_3.dae" scale="0.009 0.009 0.009" />
            </geometry>
           <origin rpy="0 0 0" xyz="0 0 0" />
            <material name="blue"/>
        </visual>
        <collision>
            <geometry>
               <mesh filename="package://inmoov_description/STL/mignolo_3.dae" scale="0.009 0.009 0.009" />
            </geometry>
             <origin rpy="0 0 0" xyz="0 0 0" />
            <material name="blue"/>
        </collision>
    </link> 

<joint name="joint_mignolo4sx" type="revolute">
        <parent link="link_mignoloterzosx"/>
        <child link="link_mignoloquartosx"/>
       <origin rpy="0 0 0" xyz="0 0 -0.2" />
        <axis xyz="0 1 0"/>
          <limit effort="1000" lower="0" upper="1.5" velocity="5"/>
    </joint>

    <link name="link_mignoloquartosx">
        <visual>
            <geometry>
                 <mesh filename="package://inmoov_description/STL/mignolo_4.dae" scale="0.009 0.009 0.009" />
            </geometry>
           <origin rpy="0 0 0" xyz="0 0 0" />
            <material name="blue"/>
        </visual>
        <collision>
            <geometry>
               <mesh filename="package://inmoov_description/STL/mignolo_4.dae" scale="0.009 0.009 0.009" />
            </geometry>
             <origin rpy="0 0 0" xyz="0 0 0" />
            <material name="blue"/>
        </collision>
    </link> 



 <joint name="spallatorsodx_joint" type="revolute">
        <parent link="torso_link"/>
        <child link="spalla1destra_link"/>
      <origin rpy="0 0 0" xyz="-1.3 0.535 2.6" />
        <axis xyz="0 1 0"/>
        <limit effort="1000" lower="0" upper="0.5" velocity="5"/>
    </joint>

<link name="spalla1destra_link">
        <visual>
            <geometry>
<mesh filename="package://inmoov_description/STL/spalladestra2b.dae" scale="0.009 0.009 0.009" />
            </geometry>
            <origin rpy="4.7 -4.726 -0.03" xyz="-0.1 -1 0.08" />
            <material name="blue"/>
        </visual>
        <collision>
            <geometry>
               <mesh filename="package://inmoov_description/STL/spalladestra2b.dae" scale="0.009 0.009 0.009" />
            </geometry>
          <origin rpy="0 0 0" xyz="0 0 0" />
            <material name="blue"/>
        </collision>
    </link>

    <joint name="joint_spalladx" type="revolute">
        <parent link="spalla1destra_link"/>
        <child link="spalla2dx_link"/>
      <origin rpy="0 0 -0.02" xyz="0.4 -0.66 -0.41" />
        <axis xyz="1 0 0"/>
        <limit effort="1000" lower="-0.4" upper="0.4" velocity="5"/>
    </joint> 

<link name="spalla2dx_link">
        <visual>
            <geometry>
<mesh filename="package://inmoov_description/STL/spalladestra1a.dae" scale="0.009 0.009 0.009" />
            </geometry>
            <origin rpy="4.7 -4.726 -0.03" xyz="-0.50 -0.39 0.5" />
            <material name="blue"/>
        </visual>
        <collision>
            <geometry>
               <mesh filename="package://inmoov_description/STL/spalladestra1a.dae" scale="0.009 0.009 0.009" />
            </geometry>
          <origin rpy="0 0 0" xyz="0 0 0" />
            <material name="blue"/>
        </collision>
    </link>

    <joint name="joint_bicipitedx" type="revolute">
        <parent link="spalla2dx_link"/>
        <child link="bicipitedx_link"/>
      <origin rpy="0 0 0" xyz="-1.027 0.04 -2.686" />
        <axis xyz="0 0 1"/>
        <limit effort="1000" lower="-0.5" upper="0" velocity="5"/>
    </joint>  


  <link name="bicipitedx_link">
        <visual>
            <geometry>
                 <mesh filename="package://inmoov_description/STL/bicipitedestrotelaio.dae" scale="0.009 0.009 0.009" />
            </geometry>
            <origin rpy="14.13 0 -4.7" xyz="-0.46 -0.43 2.165" />
            <material name="blue"/>
        </visual>
        <collision>
            <geometry>
               <mesh filename="package://inmoov_description/STL/bicipitedestrotelaio.dae" scale="0.009 0.009 0.009" />
            </geometry>
          <origin rpy="0 0 0" xyz="0 0 0" />
            <material name="blue"/>
        </collision>
    </link>

<joint name="joint_servobicipitedx2" type="revolute">
        <parent link="avambracciodx_link"/>
        <child link="servobicipitedx_link"/>
      <origin rpy="0 0 0" xyz="-0.24 -0.15 0.4" />
        <axis xyz="1 0 0"/>
        <limit effort="1000" lower="0.25" upper="0.25" velocity="5"/>
    </joint> 

  <link name="servobicipitedx_link">
        <visual>
            <geometry>
                 <mesh filename="package://inmoov_description/STL/servomotoresinistrobicipite.dae" scale="0.009 0.009 0.009" />
            </geometry>
            <origin rpy="4.7 0 -0.03" xyz="-0.73 -0.44 1.62" />
            <material name="blue"/>
        </visual>
        <collision>
            <geometry>
               <mesh filename="package://inmoov_description/STL/servomotoresinistrobicipite.dae" scale="0.009 0.009 0.009" />
            </geometry>
          <origin rpy="0 0 0" xyz="0 0 0" />
            <material name="blue"/>
        </collision>
    </link>

 <joint name="joint_avambracciodx" type="revolute">
        <parent link="bicipitedx_link"/>
        <child link="avambracciodx_link"/>
     <origin rpy="0 0 0" xyz="-0.04 0.25 0.15" />
        <axis xyz="1 0 0"/>
        <limit effort="1000" lower="-0.4" upper="0" velocity="5"/>
    </joint>  

<link name="avambracciodx_link">
        <visual>
            <geometry>
                 <mesh filename="package://inmoov_description/STL/avambracciodestro.dae" scale="0.009 0.009 0.009" />
            </geometry>
            <origin rpy="0 10.16 0" xyz="1.1 -0.07 -0.74" />
            <material name="blue"/>
        </visual>
        <collision>
            <geometry>
               <mesh filename="package://inmoov_description/STL/avambracciodestro.dae" scale="0.009 0.009 0.009" />
            </geometry>
          <origin rpy="0 0 0" xyz="0 0 0" />
            <material name="blue"/>
        </collision>
    </link>

    <joint name="joint_mano_dx" type="revolute">
        <parent link="avambracciodx_link"/>
        <child link="handdx_link"/>
      <origin rpy="0 3 0" xyz="0.06 -0.11 -0.1" />
        <axis xyz="0 1 0"/>
        <limit effort="1000" lower="0" upper="1.5" velocity="5"/>
    </joint>

<link name="handdx_link">
        <visual>
            <geometry>
                 <mesh filename="package://inmoov_description/STL/manodestra.dae" scale="0.009 0.009 0.009" />
            </geometry>
            <origin rpy="0 1.6 1.55" xyz="0.026 -2.47 0.03" />
            <material name="blue"/>
        </visual>
        <collision>
            <geometry>
               <mesh filename="package://inmoov_description/STL/manodestra.dae" scale="0.009 0.009 0.009" />
            </geometry>
          <origin rpy="7 0 0" xyz="0 -2.4 0" />
            <material name="blue"/>
        </collision>
    </link>

    <joint name="joint_pollicedx1" type="revolute">
        <parent link="handdx_link"/>
        <child link="pollice1dx_link"/>
     <origin rpy="0 0 0" xyz="0.3 -3 0.05" />
        <axis xyz="0 1 0"/>
       <limit effort="1000" lower="0" upper="1.5" velocity="5"/>
    </joint>


    <link name="pollice1dx_link">
        <visual>
            <geometry>
                 <mesh filename="package://inmoov_description/STL/pollice_destro3.dae" scale="0.009 0.009 0.009" />
            </geometry>
            <origin rpy="-0.01 0.25 0.9" xyz="0.53 -0.43 0.3" />
            <material name="blue"/>
        </visual>
        <collision>
            <geometry>
               <mesh filename="package://inmoov_description/STL/pollice_destro3.dae" scale="0.009 0.009 0.009" />
            </geometry>
           <origin rpy="0 0 0" xyz="0 0 0" />
            <material name="blue"/>
        </collision>
    </link>


    <joint name="joint_pollicedx2" type="revolute">
        <parent link="pollice1dx_link"/>
        <child link="pollice2dx_link"/>
        <origin rpy="4.9 5 0.65" xyz="0.25 -0.1 0" />
         <axis xyz="0 1 0"/>
<limit effort="1000" lower="0" upper="1.5" velocity="5"/>
    </joint>


<link name="pollice2dx_link">
        <visual>
            <geometry>
                 <mesh filename="package://inmoov_description/STL/pollice_2.dae" scale="0.009 0.009 0.009" />
            </geometry>
            <origin xyz="0.0 0.0 0.0175"/>
            <material name="blue"/>
        </visual>
        <collision>
            <geometry>
               <mesh filename="package://inmoov_description/STL/pollice_2.dae" scale="0.009 0.009 0.009" />
            </geometry>
             <origin rpy="0 0 0" xyz="0 0 0" />
            <material name="blue"/>
        </collision>
    </link>

    <joint name="joint_pollicedx3" type="revolute">
        <parent link="pollice2dx_link"/>
        <child link="pollice3dx_link"/>
       <origin rpy="0 0 0" xyz="0 0 -0.3" />
        <axis xyz="0 1 0"/>
        <limit effort="1000" lower="0" upper="1.5" velocity="5"/>
    </joint>

<link name="pollice3dx_link">
        <visual>
            <geometry>
                 <mesh filename="package://inmoov_description/STL/pollice_3.dae" scale="0.009 0.009 0.009" />
            </geometry>
            <origin xyz="0 0 0"/>
            <material name="blue"/>
        </visual>
        <collision>
            <geometry>
               <mesh filename="package://inmoov_description/STL/pollice_3.dae" scale="0.009 0.009 0.009" />
            </geometry>
           <origin rpy="9.4 0 0" xyz="0 0 0" />
            <material name="blue"/>
        </collision>
    </link>    

    <joint name="joint_indicedx1" type="revolute">
        <parent link="handdx_link"/>
        <child link="indicedx1_link"/>
      <origin rpy="-3.06 4.7 -1.53" xyz="0.31 -3.553 0.08" />
      <axis xyz="0 1 0"/>
 <limit effort="1000" lower="-1.5" upper="0" velocity="5"/>
    </joint>

   <link name="indicedx1_link">
        <visual>
            <geometry>
                 <mesh filename="package://inmoov_description/STL/indice1.dae" scale="0.009 0.009 0.009" />
            </geometry>
             <origin rpy="0 0 0" xyz="0 0 0.32" />
            <material name="blue"/>
        </visual>
        <collision>
            <geometry>
               <mesh filename="package://inmoov_description/STL/indice1.dae" scale="0.009 0.009 0.009" />
            </geometry>
            <origin rpy="0 0 0" xyz="0 0 0.32" />
            <material name="blue"/>
        </collision>
    </link> 

    <joint name="joint_indicedx2" type="revolute">
        <parent link="indicedx1_link"/>
        <child link="indicedx2_link"/>
        <origin rpy="0 0 0" xyz="0 0 0.35" />
        <axis xyz="0 1 0"/>
        <limit effort="1000" lower="-1.5" upper="0" velocity="5"/>
    </joint>

    <link name="indicedx2_link">
        <visual>
            <geometry>
                 <mesh filename="package://inmoov_description/STL/indice2.dae" scale="0.009 0.009 0.009" />
            </geometry>
            <origin rpy="9.4 0 0" xyz="0 0 -0.025" />
            <material name="blue"/>
        </visual>
        <collision>
            <geometry>
               <mesh filename="package://inmoov_description/STL/indice2.dae" scale="0.009 0.009 0.009" />
            </geometry>
           <origin rpy="9.4 0 0" xyz="0 0 -0.025" />
            <material name="blue"/>
        </collision>
    </link> 

    <joint name="joint_indicedx3" type="revolute">
        <parent link="indicedx2_link"/>
        <child link="indicedx3_link"/>
      <origin rpy="0 0 0" xyz="0 0.005 0.2" />
      <axis xyz="0 1 0"/>
 <limit effort="1000" lower="-1.5" upper="0" velocity="5"/>
    </joint>

    <link name="indicedx3_link">
        <visual>
            <geometry>
                 <mesh filename="package://inmoov_description/STL/indice3.dae" scale="0.009 0.009 0.009" />
            </geometry>
            <origin rpy="9.4 0 0" xyz="0 0 -0.01" />
            <material name="blue"/>
        </visual>
        <collision>
            <geometry>
               <mesh filename="package://inmoov_description/STL/indice3.dae" scale="0.009 0.009 0.009" />
            </geometry>
             <origin rpy="9.4 0 0" xyz="0 0 -0.01" />
            <material name="blue"/>
        </collision>
    </link> 

    <joint name="joint_mediodx1" type="revolute">
        <parent link="handdx_link"/>
        <child link="mediodx1_link"/>
       <origin rpy="-3.14 4.7 -1.565" xyz="0.065 -3.58 0.08" />
        <axis xyz="0 1 0"/>
       <limit effort="1000" lower="-1.5" upper="0" velocity="5"/>
    </joint>

    <link name="mediodx1_link">
        <visual>
            <geometry>
                 <mesh filename="package://inmoov_description/STL/medio_1.dae" scale="0.009 0.009 0.009" />
            </geometry>
           <origin rpy="0 0 0" xyz="0 0 0.35" />
            <material name="blue"/>
        </visual>
        <collision>
            <geometry>
               <mesh filename="package://inmoov_description/STL/medio_1.dae" scale="0.009 0.009 0.009" />
            </geometry>
             <origin rpy="0 0 0" xyz="0 0 0.35" />
            <material name="blue"/>
        </collision>
    </link> 

    <joint name="joint_mediodx2" type="revolute">
        <parent link="mediodx1_link"/>
        <child link="mediodx2_link"/>
          <origin rpy="0 0 0" xyz="0 0 0.35" />
        <axis xyz="0 1 0"/>
        <limit effort="1000" lower="-1.5" upper="0" velocity="5"/>
    </joint>

    <link name="mediodx2_link">
        <visual>
            <geometry>
                 <mesh filename="package://inmoov_description/STL/medio_2.dae" scale="0.009 0.009 0.009" />
            </geometry>
              <origin rpy="9.4 0 0" xyz="0 0 0.015" />
            <material name="blue"/>
        </visual>
        <collision>
            <geometry>
               <mesh filename="package://inmoov_description/STL/medio_2.dae" scale="0.009 0.009 0.009" />
            </geometry>
             <origin rpy="9.4 0 0" xyz="0 0 0.015" />
            <material name="blue"/>
        </collision>
    </link> 

    <joint name="joint_mediodx3" type="revolute">
        <parent link="mediodx2_link"/>
        <child link="mediodx3_link"/>
         <origin rpy="0 0 0" xyz="0 0 0.22" />
      <axis xyz="0 1 0"/>
 <limit effort="1000" lower="-1.5" upper="0" velocity="5"/>    
   </joint>

    <link name="mediodx3_link">
        <visual>
            <geometry>
                 <mesh filename="package://inmoov_description/STL/medio_3.dae" scale="0.009 0.009 0.009" />
            </geometry>
             <origin rpy="9.4 0 0" xyz="0 0 0.02" />
            <material name="blue"/>
        </visual>
        <collision>
            <geometry>
               <mesh filename="package://inmoov_description/STL/medio_3.dae" scale="0.009 0.009 0.009" />
            </geometry>
             <origin rpy="9.4 0 0" xyz="0 0 0.02" />
            <material name="blue"/>
        </collision>
    </link> 


     <joint name="joint_anularedx1" type="revolute">
        <parent link="handdx_link"/>
        <child link="anulare1dx_link"/>
       <origin rpy="-3.22 4.7 -1.565" xyz="-0.22 -3.495 0.08" />
        <axis xyz="0 1 0"/>
        <limit effort="1000" lower="-1.5" upper="0" velocity="5"/>
    </joint>

    <link name="anulare1dx_link">
        <visual>
            <geometry>
                 <mesh filename="package://inmoov_description/STL/anulare_2.dae" scale="0.009 0.009 0.009" />
            </geometry>
              <origin rpy="9.4 0 0" xyz="0 0 0" />
            <material name="blue"/>
        </visual>
        <collision>
            <geometry>
               <mesh filename="package://inmoov_description/STL/anulare_2.dae" scale="0.009 0.009 0.009" />
            </geometry>
             <origin rpy="9.4 0 0" xyz="0 0 0" />
            <material name="blue"/>
        </collision>
    </link> 

    <joint name="joint_anularedx2" type="revolute">
        <parent link="anulare1dx_link"/>
        <child link="anulare2dx_link"/>
         <origin rpy="0 0 0" xyz="0 0 0.32" />
      <axis xyz="0 1 0"/>
 <limit effort="1000" lower="-1.5" upper="0" velocity="5"/>
    </joint>

    <link name="anulare2dx_link">
        <visual>
            <geometry>
                 <mesh filename="package://inmoov_description/STL/anulare_3.dae" scale="0.009 0.009 0.009" />
            </geometry>
             <origin rpy="9.4 0 0" xyz="0 0 0" />
            <material name="blue"/>
        </visual>
        <collision>
            <geometry>
               <mesh filename="package://inmoov_description/STL/anulare_3.dae" scale="0.009 0.009 0.009" />
            </geometry>
             <origin rpy="9.4 0 0" xyz="0 0 0.02" />
            <material name="blue"/>
        </collision>
    </link> 

 <joint name="joint_anularedx3" type="revolute">
        <parent link="anulare2dx_link"/>
        <child link="anulare3dx_link"/>
         <origin rpy="0 0 0" xyz="0 0 0.2" />
      <axis xyz="0 1 0"/>
<limit effort="1000" lower="-1.5" upper="0" velocity="5"/>
    </joint>

    <link name="anulare3dx_link">
        <visual>
            <geometry>
                 <mesh filename="package://inmoov_description/STL/anulare_4.dae" scale="0.009 0.009 0.009" />
            </geometry>
             <origin rpy="9.4 0 0" xyz="0 0 0" />
            <material name="blue"/>
        </visual>
        <collision>
            <geometry>
               <mesh filename="package://inmoov_description/STL/anulare_4.dae" scale="0.009 0.009 0.009" />
            </geometry>
             <origin rpy="9.4 0 0" xyz="0 0 0" />
            <material name="blue"/>
        </collision>
    </link> 


 <joint name="joint_mignolodx1" type="revolute">
        <parent link="handdx_link"/>
        <child link="linkdx_mignoloprimo"/>
       <origin rpy="-0.225 4.7 -1.565" xyz="-0.437 -3.38 0.08" />
        <axis xyz="0 1 0"/>
       <limit effort="1000" lower="0" upper="1.5" velocity="5"/>
    </joint>

    <link name="linkdx_mignoloprimo">
        <visual>
            <geometry>
                 <mesh filename="package://inmoov_description/STL/mignolo_2.dae" scale="0.009 0.009 0.009" />
            </geometry>
           <origin rpy="0 0 0" xyz="0 0 0" />
            <material name="blue"/>
        </visual>
        <collision>
            <geometry>
               <mesh filename="package://inmoov_description/STL/mignolo_2.dae" scale="0.009 0.009 0.009" />
            </geometry>
             <origin rpy="0 0 0" xyz="0 0 0" />
            <material name="blue"/>
        </collision>
    </link> 

<joint name="joint_mignolodx2" type="revolute">
        <parent link="linkdx_mignoloprimo"/>
        <child link="linkdx_mignolosecondo"/>
       <origin rpy="0 0 0" xyz="0 0 -0.3" />
        <axis xyz="0 1 0"/>
       <limit effort="1000" lower="0" upper="1.5" velocity="5"/>
    </joint>

    <link name="linkdx_mignolosecondo">
        <visual>
            <geometry>
                 <mesh filename="package://inmoov_description/STL/mignolo_3.dae" scale="0.009 0.009 0.009" />
            </geometry>
           <origin rpy="0 0 0" xyz="0 0 0" />
            <material name="blue"/>
        </visual>
        <collision>
            <geometry>
               <mesh filename="package://inmoov_description/STL/mignolo_3.dae" scale="0.009 0.009 0.009" />
            </geometry>
             <origin rpy="0 0 0" xyz="0 0 0" />
            <material name="blue"/>
        </collision>
    </link> 

<joint name="joint_mignolodx3" type="revolute">
        <parent link="linkdx_mignolosecondo"/>
        <child link="linkdx_mignoloterzo"/>
       <origin rpy="0 0 0" xyz="0 0 -0.2" />
        <axis xyz="0 1 0"/>
        <limit effort="1000" lower="0" upper="1.5" velocity="5"/>
    </joint>

    <link name="linkdx_mignoloterzo">
        <visual>
            <geometry>
                 <mesh filename="package://inmoov_description/STL/mignolo_4.dae" scale="0.009 0.009 0.009" />
            </geometry>
           <origin rpy="0 0 0" xyz="0 0 0" />
            <material name="blue"/>
        </visual>
        <collision>
            <geometry>
               <mesh filename="package://inmoov_description/STL/mignolo_4.dae" scale="0.009 0.009 0.009" />
            </geometry>
             <origin rpy="0 0 0" xyz="0 0 0" />
            <material name="blue"/>
        </collision>
    </link> 


     
</robot>
